Workbook

Sheet Léeme
A1: Matriz Maestra de Reprogramación – Cronograma Integrado AFSP
A2: Propuesta técnica de solución · Escenario 2 (Integración optimizada) · Corte del .mpp: 21/10/2026
A4: Cómo usar este libro
A5: 1. «Matriz maestra»: actividades que cambian, con fechas actuales y propuestas. Filtre por sistema, macroproceso, prioridad, responsable o estado.
A6: 2. «Dependencias»: predecesoras y sucesoras propuestas para Microsoft Project, con la holgura verificada.
A7: 3. «Importar a Project»: filas listas para cargar. También se entrega un archivo XML que Microsoft Project abre directamente.
A8: 4. «Validación diagnóstico», «Alternativas», «Escenarios», «Hitos», «Plan de acción», «Decisiones» y «Antes y después» sustentan la propuesta.
A10: Celdas editables
A11: En «Matriz maestra», los CAF pueden ajustar las columnas en amarillo: Inicio propuesto, Fin propuesto, Prioridad, Responsable y Estado de la fecha. La variación se recalcula sola.
A13: Estados de la fecha
A14: Calculada: obtenida con el calendario del .mpp y la red de vínculos. Tentativa: requiere validar capacidad del CAF. Pendiente de decisión: depende de una decisión de la Coordinación o la UCP.
A16: Advertencias
... A20: • Las tareas nuevas usan códigos N# (tareas), M# (entregas parciales) y H# (hitos de integración).

Sheet Resumen
A1: Resumen de la reprogramación (se actualiza con la Matriz maestra)
A3: Sistema | B3: Actividades | C3: Prioridad alta | D3: Calculadas | E3: Tentativas | F3: Pendientes de decisión | G3: Mayor variación de fin (días)
A4: Presupuesto | B4: =COUNTIF('Matriz maestra'!$B$3:$B$43,A4) -> 16 | C4: =COUNTIFS('Matriz maestra'!$B$3:$B$43,A4,'Matriz maestra'!$P$3:$P$43,"Alta") -> 11 | D4: =COUNTIFS('Matriz maestra'!$B$3:$B$43,A4,'Matriz maestra'!$R$3:$R$43,"Calculada") -> 10 | E4: =COUNTIFS('Matriz maestra'!$B$3:$B$43,A4,'Matriz maestra'!$R$3:$R$43,"Tentativa") -> 6 | F4: =COUNTIFS('Matriz maestra'!$B$3:$B$43,A4,'Matriz maestra'!$R$3:$R$43,"Pendiente de decisión") -> 0 | G4: =_xlfn.MAXIFS('Matriz maestra'!$K$3:$K$43,'Matriz maestra'!$B$3:$B$43,A4) -> 177
A5: Inversiones | B5: =COUNTIF('Matriz maestra'!$B$3:$B$43,A5) -> 2 | C5: =COUNTIFS('Matriz maestra'!$B$3:$B$43,A5,'Matriz maestra'!$P$3:$P$43,"Alta") -> 2 | D5: =COUNTIFS('Matriz maestra'!$B$3:$B$43,A5,'Matriz maestra'!$R$3:$R$43,"Calculada") -> 0 | E5: =COUNTIFS('Matriz maestra'!$B$3:$B$43,A5,'Matriz maestra'!$R$3:$R$43,"Tentativa") -> 1 | F5: =COUNTIFS('Matriz maestra'!$B$3:$B$43,A5,'Matriz maestra'!$R$3:$R$43,"Pendiente de decisión") -> 1 | G5: =_xlfn.MAXIFS('Matriz maestra'!$K$3:$K$43,'Matriz maestra'!$B$3:$B$43,A5) -> 6
A6: Abastecimiento | B6: =COUNTIF('Matriz maestra'!$B$3:$B$43,A6) -> 3 | C6: =COUNTIFS('Matriz maestra'!$B$3:$B$43,A6,'Matriz maestra'!$P$3:$P$43,"Alta") -> 2 | D6: =COUNTIFS('Matriz maestra'!$B$3:$B$43,A6,'Matriz maestra'!$R$3:$R$43,"Calculada") -> 0 | E6: =COUNTIFS('Matriz maestra'!$B$3:$B$43,A6,'Matriz maestra'!$R$3:$R$43,"Tentativa") -> 3 | F6: =COUNTIFS('Matriz maestra'!$B$3:$B$43,A6,'Matriz maestra'!$R$3:$R$43,"Pendiente de decisión") -> 0 | G6: =_xlfn.MAXIFS('Matriz maestra'!$K$3:$K$43,'Matriz maestra'!$B$3:$B$43,A6) -> 0
A7: GFRH | B7: =COUNTIF('Matriz maestra'!$B$3:$B$43,A7) -> 2 | C7: =COUNTIFS('Matriz maestra'!$B$3:$B$43,A7,'Matriz maestra'!$P$3:$P$43,"Alta") -> 0 | D7: =COUNTIFS('Matriz maestra'!$B$3:$B$43,A7,'Matriz maestra'!$R$3:$R$43,"Calculada") -> 1 | E7: =COUNTIFS('Matriz maestra'!$B$3:$B$43,A7,'Matriz maestra'!$R$3:$R$43,"Tentativa") -> 1 | F7: =COUNTIFS('Matriz maestra'!$B$3:$B$43,A7,'Matriz maestra'!$R$3:$R$43,"Pendiente de decisión") -> 0 | G7: =_xlfn.MAXIFS('Matriz maestra'!$K$3:$K$43,'Matriz maestra'!$B$3:$B$43,A7) -> 30
A8: Tesorería | B8: =COUNTIF('Matriz maestra'!$B$3:$B$43,A8) -> 5 | C8: =COUNTIFS('Matriz maestra'!$B$3:$B$43,A8,'Matriz maestra'!$P$3:$P$43,"Alta") -> 2 | D8: =COUNTIFS('Matriz maestra'!$B$3:$B$43,A8,'Matriz maestra'!$R$3:$R$43,"Calculada") -> 3 | E8: =COUNTIFS('Matriz maestra'!$B$3:$B$43,A8,'Matriz maestra'!$R$3:$R$43,"Tentativa") -> 2 | F8: =COUNTIFS('Matriz maestra'!$B$3:$B$43,A8,'Matriz maestra'!$R$3:$R$43,"Pendiente de decisión") -> 0 | G8: =_xlfn.MAXIFS('Matriz maestra'!$K$3:$K$43,'Matriz maestra'!$B$3:$B$43,A8) -> 42
A9: Endeudamiento | B9: =COUNTIF('Matriz maestra'!$B$3:$B$43,A9) -> 2 | C9: =COUNTIFS('Matriz maestra'!$B$3:$B$43,A9,'Matriz maestra'!$P$3:$P$43,"Alta") -> 2 | D9: =COUNTIFS('Matriz maestra'!$B$3:$B$43,A9,'Matriz maestra'!$R$3:$R$43,"Calculada") -> 0 | E9: =COUNTIFS('Matriz maestra'!$B$3:$B$43,A9,'Matriz maestra'!$R$3:$R$43,"Tentativa") -> 2 | F9: =COUNTIFS('Matriz maestra'!$B$3:$B$43,A9,'Matriz maestra'!$R$3:$R$43,"Pendiente de decisión") -> 0 | G9: =_xlfn.MAXIFS('Matriz maestra'!$K$3:$K$43,'Matriz maestra'!$B$3:$B$43,A9) -> 0
A10: Contabilidad | B10: =COUNTIF('Matriz maestra'!$B$3:$B$43,A10) -> 4 | C10: =COUNTIFS('Matriz maestra'!$B$3:$B$43,A10,'Matriz maestra'!$P$3:$P$43,"Alta") -> 0 | D10: =COUNTIFS('Matriz maestra'!$B$3:$B$43,A10,'Matriz maestra'!$R$3:$R$43,"Calculada") -> 0 | E10: =COUNTIFS('Matriz maestra'!$B$3:$B$43,A10,'Matriz maestra'!$R$3:$R$43,"Tentativa") -> 4 | F10: =COUNTIFS('Matriz maestra'!$B$3:$B$43,A10,'Matriz maestra'!$R$3:$R$43,"Pendiente de decisión") -> 0 | G10: =_xlfn.MAXIFS('Matriz maestra'!$K$3:$K$43,'Matriz maestra'!$B$3:$B$43,A10) -> 0
A11: Transversal | B11: =COUNTIF('Matriz maestra'!$B$3:$B$43,A11) -> 7 | C11: =COUNTIFS('Matriz maestra'!$B$3:$B$43,A11,'Matriz maestra'!$P$3:$P$43,"Alta") -> 7 | D11: =COUNTIFS('Matriz maestra'!$B$3:$B$43,A11,'Matriz maestra'!$R$3:$R$43,"Calculada") -> 7 | E11: =COUNTIFS('Matriz maestra'!$B$3:$B$43,A11,'Matriz maestra'!$R$3:$R$43,"Tentativa") -> 0 | F11: =COUNTIFS('Matriz maestra'!$B$3:$B$43,A11,'Matriz maestra'!$R$3:$R$43,"Pendiente de decisión") -> 0 | G11: =_xlfn.MAXIFS('Matriz maestra'!$K$3:$K$43,'Matriz maestra'!$B$3:$B$43,A11) -> 0
A12: Total | B12: =SUM(B4:B11) -> 41 | C12: =SUM(C4:C11) -> 26 | D12: =SUM(D4:D11) -> 21 | E12: =SUM(E4:E11) -> 19 | F12: =SUM(F4:F11) -> 1
A14: Nota: la columna «Mayor variación de fin» considera solo actividades existentes con fecha actual. Las tareas nuevas no tienen variación.

Sheet Matriz maestra
A1: Actividades que requieren modificación (Escenario 2). Columnas amarillas editables; la variación se recalcula. Filtros activos en el encabezado.
A2: ID Project / código | B2: Sistema | C2: Macroproceso | D2: Actividad | E2: Tipo de cambio | F2: Inicio actual | G2: Fin actual | H2: Inicio propuesto | I2: Fin propuesto | J2: Variación inicio (días) | K2: Variación fin (días) | L2: Duración propuesta (días háb.) | M2: Predecesoras propuestas | N2: Sucesoras | O2: Caso | P2: Prioridad | Q2: Responsable (CAF) | R2: Estado de la fecha | S2: Escenario | T2: Justificación
A3: M1 | B3: Abastecimiento | C3: Gestión | D3: Hito: interfaz de contrato, OC y OS aprobada (entrega parcial de 196) | E3: Hito | H3: 46567 | I3: 46567 | J3: =IF(AND(F3<>"",H3<>""),H3-F3,"") | K3: =IF(AND(G3<>"",I3<>""),I3-G3,"") | L3: 0 | M3: 196CC+32 días | N3: 181 | O3: C2 | P3: Alta | Q3: CAF Abastecimiento | R3: Tentativa | S3: E2 | T3: Entrega parcial de 196: estructura de datos del contrato y de la orden, suficiente para diseñar el compromiso.
A4: M2 | B4: Abastecimiento | C4: Gestión | D4: Hito: interfaz de Conformidad aprobada (entrega parcial de 197) | E4: Hito | H4: 46689 | I4: 46689 | J4: =IF(AND(F4<>"",H4<>""),H4-F4,"") | K4: =IF(AND(G4<>"",I4<>""),I4-G4,"") | L4: 0 | M4: 197CC+42 días | N4: N3 | O4: C2 | P4: Alta | Q4: CAF Abastecimiento | R4: Tentativa | S4: E2 | T4: Entrega parcial de 197: datos de la conformidad que habilitan el devengado.
A5: M5 | B5: Endeudamiento | C5: Clasificadores y Catálogos | D5: Hito: estructura del Catálogo relacional Deuda–Inversión aprobada | E5: Hito | H5: 46356 | I5: 46356 | J5: =IF(AND(F5<>"",H5<>""),H5-F5,"") | K5: =IF(AND(G5<>"",I5<>""),I5-G5,"") | L5: 0 | M5: 82CC+20 días | N5: 149, 257 | O5: C5 | P5: Alta | Q5: CAF Endeudamiento + CAF Inversiones | R5: Tentativa | S5: E2 | T5: Entrega parcial de 82 que necesitan 149 y 256.
A6: M8 | B6: Endeudamiento | C6: Programación | D6: Hito: proyección preliminar del servicio de deuda para la Formulación | E6: Hito | H6: 46402 | I6: 46402 | J6: =IF(AND(F6<>"",H6<>""),H6-F6,"") | K6: =IF(AND(G6<>"",I6<>""),I6-G6,"") | L6: 0 | M6: 168FF-10 días | N6: 144 | O6: C4 | P6: Alta | Q6: CAF Endeudamiento | R6: Tentativa | S6: E2 | T6: Versión preliminar de 167/169 para que la Formulación (144) cierre con el dato de deuda. Se mantiene la restricción de 165 y 170.
A7: 147 | B7: Inversiones | C7: Programación | D7: Elaboración de la PMI y PMIE | E7: Reactivar y extender | F7: 46266 | G7: 46356 | H7: 46266 | I7: 46360 | J7: =IF(AND(F7<>"",H7<>""),H7-F7,"") -> 0 | K7: =IF(AND(G7<>"",I7<>""),I7-G7,"") -> 4 | L7: 65 | N7: 149 | O7: C5 | P7: Alta | Q7: CAF Inversiones | R7: Pendiente de decisión | S7: E2 | T7: Sale de StandBy el 2026-11-02; le quedan unos 25 días (38 % de 65). Es predecesora de 149.
A8: 149 | B8: Inversiones | C8: Programación | D8: Registro estructura del Proyecto y su relación con la Estructura Presupuestaria | E8: Mover | F8: 46357 | G8: 46417 | H8: 46363 | I8: 46423 | J8: =IF(AND(F8<>"",H8<>""),H8-F8,"") -> 6 | K8: =IF(AND(G8<>"",I8<>""),I8-G8,"") -> 6 | L8: 45 | M8: 147FC; M5FC | N8: 150, H2 | O8: C5 | P8: Alta | Q8: CAF Inversiones | R8: Tentativa | S8: E2 | T8: Empieza cuando la PMI esté aprobada (147). Conserva su duración.
A9: 46 | B9: Presupuesto | C9: Clasificadores y Catálogos | D9: Catálogo de relación Estructura Funcional Programática - EFP | E9: Regularizar cierre | F9: 45980 | G9: 46177 | H9: 45980 | I9: 46339 | J9: =IF(AND(F9<>"",H9<>""),H9-F9,"") -> 0 | K9: =IF(AND(G9<>"",I9<>""),I9-G9,"") -> 162 | L9: 142 | N9: M3 | O9: C4 | P9: Alta | Q9: CAF Presupuesto | R9: Calculada | S9: E2 | T9: Vencida al 99 %. Se fija el cierre formal del MFD para que pueda usarse como insumo.
A10: 62 | B10: Presupuesto | C10: Clasificadores y Catálogos | D10: Gestor de responsables (responsables por equipo) | E10: Regularizar cierre | F10: 45999 | G10: 46162 | H10: 45999 | I10: 46339 | J10: =IF(AND(F10<>"",H10<>""),H10-F10,"") -> 0 | K10: =IF(AND(G10<>"",I10<>""),I10-G10,"") -> 177 | L10: 118 | O10: C4 | P10: Alta | Q10: CAF Presupuesto | R10: Calculada | S10: E2 | T10: Vencida al 99 %. Se fija el cierre formal del MFD para que pueda usarse como insumo.
A11: 25 | B11: Presupuesto | C11: Clasificadores y Catálogos | D11: Catálogo de Finalidades / Sub actividad | E11: Regularizar cierre | F11: 46063 | G11: 46176 | H11: 46063 | I11: 46339 | J11: =IF(AND(F11<>"",H11<>""),H11-F11,"") -> 0 | K11: =IF(AND(G11<>"",I11<>""),I11-G11,"") -> 163 | L11: 82 | O11: C4 | P11: Alta | Q11: CAF Presupuesto | R11: Calculada | S11: E2 | T11: Vencida al 99 %. Se fija el cierre formal del MFD para que pueda usarse como insumo.
A12: 59 | B12: Presupuesto | C12: Clasificadores y Catálogos | D12: Catálogo de equipo de trabajo | E12: Regularizar cierre | F12: 46118 | G12: 46265 | H12: 46118 | I12: 46339 | J12: =IF(AND(F12<>"",H12<>""),H12-F12,"") -> 0 | K12: =IF(AND(G12<>"",I12<>""),I12-G12,"") -> 74 | L12: 106 | O12: C4 | P12: Alta | Q12: CAF Presupuesto | R12: Calculada | S12: E2 | T12: Vencida al 99 %. Se fija el cierre formal del MFD para que pueda usarse como insumo.
A13: 60 | B13: Presupuesto | C13: Clasificadores y Catálogos | D13: Catálogo criterio de conformación | E13: Regularizar cierre | F13: 46118 | G13: 46265 | H13: 46118 | I13: 46339 | J13: =IF(AND(F13<>"",H13<>""),H13-F13,"") -> 0 | K13: =IF(AND(G13<>"",I13<>""),I13-G13,"") -> 74 | L13: 106 | O13: C4 | P13: Alta | Q13: CAF Presupuesto | R13: Calculada | S13: E2 | T13: Vencida al 99 %. Se fija el cierre formal del MFD para que pueda usarse como insumo.
A14: 63 | B14: Presupuesto | C14: Clasificadores y Catálogos | D14: Catálogo de Grupo de Trabajo | E14: Regularizar cierre | F14: 46266 | G14: 46295 | H14: 46266 | I14: 46339 | J14: =IF(AND(F14<>"",H14<>""),H14-F14,"") -> 0 | K14: =IF(AND(G14<>"",I14<>""),I14-G14,"") -> 44 | L14: 22 | O14: C4 | P14: Alta | Q14: CAF Presupuesto | R14: Calculada | S14: E2 | T14: Vencida al 99 %. Se fija el cierre formal del MFD para que pueda usarse como insumo.
A15: M3 | B15: Presupuesto | C15: Clasificadores y Catálogos | D15: Hito: versión mínima de catálogos para Programación (estructura aprobada) | E15: Hito | H15: 46402 | I15: 46402 | J15: =IF(AND(F15<>"",H15<>""),H15-F15,"") | K15: =IF(AND(G15<>"",I15<>""),I15-G15,"") | L15: 0 | M15: 46FC; 65FC; 66FC; 129FC; 130FC; 131FC; 128CC+40 días; 132CC+40 días | N15: 144, H1 | O15: C4 | P15: Alta | Q15: CAF Presupuesto | R15: Tentativa | S15: E2 | T15: Estructura (atributos y relaciones) aprobada de 46, 47, 65, 66 y 128–132. El poblado completo puede seguir después.
A16: M4 | B16: Presupuesto | C16: Programación | D16: Hito: estructura de metas v1 aprobada (entrega parcial de 140) | E16: Hito | H16: 46402 | I16: 46402 | J16: =IF(AND(F16<>"",H16<>""),H16-F16,"") | K16: =IF(AND(G16<>"",I16<>""),I16-G16,"") | L16: 0 | M16: 140CC+30 días | N16: 144 | O16: C4 | P16: Alta | Q16: CAF Presupuesto | R16: Tentativa | S16: E2 | T16: La Formulación (144) cierra su MFD con la estructura de metas; el Administrador de Metas (140) se completa para la Apertura.
A17: N2 | B17: Presupuesto | C17: Gestión | D17: Certificación y modelo común de datos del gasto (certificación, compromiso y devengado) | E17: Nueva tarea | H17: 46419 | I17: 46479 | J17: =IF(AND(F17<>"",H17<>""),H17-F17,"") | K17: =IF(AND(G17<>"",I17<>""),I17-G17,"") | L17: 45 | N17: 195, 181, 182, 236, 234 | O17: C2 | P17: Alta | Q17: CAF Presupuesto + CAF Abastecimiento + CAF Tesorería | R17: Tentativa | S17: E2 | T17: Las Actuaciones preparatorias (195) requieren la certificación de crédito, y Pagos (234, 236) requiere el modelo del devengado. Duración igual a la de la fila 181 (45 días).
A18: 181 | B18: Presupuesto | C18: Gestión | D18: Compromiso de gastos de bienes, servicios y obras | E18: Mover y renombrar | F18: 46539 | G18: 46599 | H18: 46568 | I18: 46630 | J18: =IF(AND(F18<>"",H18<>""),H18-F18,"") -> 29 | K18: =IF(AND(G18<>"",I18<>""),I18-G18,"") -> 31 | L18: 45 | M18: N2FC; M1FC; 175FC; 176FC | N18: N3, H4 | O18: C2 | P18: Alta | Q18: CAF Presupuesto | R18: Tentativa | S18: E2 | T18: Se diseña con la interfaz de la orden (M1) aprobada. Conserva su duración (45 días).
A19: N3 | B19: Presupuesto | C19: Gestión | D19: Devengado de gastos de bienes, servicios y obras | E19: Nueva tarea | H19: 46692 | I19: 46745 | J19: =IF(AND(F19<>"",H19<>""),H19-F19,"") | K19: =IF(AND(G19<>"",I19<>""),I19-G19,"") | L19: 40 | M19: M2FC; 181FC | N19: N5, 369, H4 | O19: C2 | P19: Alta | Q19: CAF Presupuesto + CAF Abastecimiento | R19: Tentativa | S19: E2 | T19: Separa el devengado del compromiso para alinearlo con la Conformidad (197).
A20: M9 | B20: Tesorería | C20: Programación | D20: Hito: estimación preliminar de ingresos por OOC, RO y RD para la Formulación | E20: Hito | H20: 46402 | I20: 46402 | J20: =IF(AND(F20<>"",H20<>""),H20-F20,"") | K20: =IF(AND(G20<>"",I20<>""),I20-G20,"") | L20: 0 | M20: 160FF-10 días | N20: 144 | O20: C4 | P20: Alta | Q20: CAF Tesorería | R20: Tentativa | S20: E2 | T20: Versión preliminar de 160 para la Formulación (144).
A21: N1 | B21: Tesorería | C21: Programación | D21: Asignación de pago – versión mínima (cuota de pago v1 con reglas vigentes) | E21: Nueva tarea | H21: 46510 | I21: 46540 | J21: =IF(AND(F21<>"",H21<>""),H21-F21,"") | K21: =IF(AND(G21<>"",I21<>""),I21-G21,"") | L21: 23 | M21: 161FC | N21: 236, 234, 235, 233 | O21: C1 | P21: Alta | Q21: CAF Tesorería | R21: Tentativa | S21: E2 | T21: Habilita los pagos que se diseñan desde el 16/06/2027 (236) usando los flujos de caja proyectados (161). Se conserva la duración de la fila 163 (23 días).
A22: N5 | B22: Contabilidad | C22: Evaluación | D22: Adecuación de cierres y estados presupuestales a las fuentes AFSP | E22: Nueva tarea | H22: 46748 | I22: 46801 | J22: =IF(AND(F22<>"",H22<>""),H22-F22,"") | K22: =IF(AND(G22<>"",I22<>""),I22-G22,"") | L22: 40 | M22: N3FC | N22: 363 | O22: C3 | P22: Media | Q22: CAF Contabilidad + CAF Presupuesto | R22: Tentativa | S22: E2 | T22: Escenario A: los cierres de 2026–2027 usan el SIAF-SP (integración 344 concluida). Esta tarea adapta 355, 358, 359 y 360 cuando exista la ejecución AFSP, antes de la Cuenta General (363).
A23: N6 | B23: Contabilidad | C23: Gestión | D23: Actualización 3 de Catálogo de Eventos y Motor de Contabilización | E23: Nueva tarea | H23: 47210 | I23: 47270 | J23: =IF(AND(F23<>"",H23<>""),H23-F23,"") | K23: =IF(AND(G23<>"",I23<>""),I23-G23,"") | L23: 45 | M23: 347FC | N23: N7 | O23: C6 | P23: Media | Q23: CAF Contabilidad + CAF Endeudamiento | R23: Tentativa | S23: E2 | T23: Cubre los eventos de Endeudamiento etapa 2 y de Abastecimiento diseñados entre oct 2028 y mar 2029.
A24: N7 | B24: Contabilidad | C24: Gestión | D24: Actualización 4 de Catálogo de Eventos y Motor de Contabilización | E24: Nueva tarea | H24: 47392 | I24: 47480 | J24: =IF(AND(F24<>"",H24<>""),H24-F24,"") | K24: =IF(AND(G24<>"",I24<>""),I24-G24,"") | L24: 65 | M24: N6FC; 296FF | N24: N10, H7 | O24: C6 | P24: Media | Q24: CAF Contabilidad + CAF Endeudamiento + CAF Abastecimiento | R24: Tentativa | S24: E2 | T24: Cierra la cobertura contable de los procesos diseñados hasta dic 2029; termina con el proyecto (FF con 296).
A25: N10 | B25: Contabilidad | C25: Evaluación | D25: Validación de la integración Gestión 2028–2029 con Cuenta General y Estadísticas de Finanzas Públicas | E25: Nueva tarea | H25: 47392 | I25: 47480 | J25: =IF(AND(F25<>"",H25<>""),H25-F25,"") | K25: =IF(AND(G25<>"",I25<>""),I25-G25,"") | L25: 65 | M25: 363FC; N7FF | N25: H7 | O25: C7 | P25: Media | Q25: CAF Contabilidad + CAF Endeudamiento + CAF Abastecimiento | R25: Tentativa | S25: E2 | T25: Evaluación termina en 2028, pero Endeudamiento y Abastecimiento diseñan hasta 2029: se valida que sus datos lleguen a 363 y 364.
A26: 81 | B26: GFRH | C26: Clasificadores y Catálogos | D26: Catálogo GFRH por definir (antes «<Tarea nueva>») | E26: Reprogramar por avance real | F26: 46296 | G26: 46384 | H26: 46328 | I26: 46414 | J26: =IF(AND(F26<>"",H26<>""),H26-F26,"") -> 32 | K26: =IF(AND(G26<>"",I26<>""),I26-G26,"") -> 30 | L26: 63 | O26: Calidad | P26: Media | Q26: CAF GFRH | R26: Calculada | S26: E2 | T26: Debió iniciar antes del corte y sigue en 0 %. Se mueve el inicio al corte y se conserva la duración.
A27: M6 | B27: GFRH | C27: Gestión | D27: Hito: interfaz planilla–compromiso–devengado–pago validada con GFRH | E27: Hito | H27: 46610 | I27: 46610 | J27: =IF(AND(F27<>"",H27<>""),H27-F27,"") | K27: =IF(AND(G27<>"",I27<>""),I27-G27,"") | L27: 0 | M27: 182CC+40 días | O27: C7 | P27: Media | Q27: CAF GFRH + CAF Presupuesto + CAF Tesorería | R27: Tentativa | S27: E2 | T27: GFRH concluyó su diseño en 2026; se valida su interfaz dentro de la Ejecución de gestión fiscal (182).
A28: 48 | B28: Presupuesto | C28: Clasificadores y Catálogos | D28: Clasificador de Recursos hidricos y saneamiento | E28: Reprogramar por avance real | F28: 46302 | G28: 46393 | H28: 46328 | I28: 46419 | J28: =IF(AND(F28<>"",H28<>""),H28-F28,"") -> 26 | K28: =IF(AND(G28<>"",I28<>""),I28-G28,"") -> 26 | L28: 66 | O28: C4 | P28: Media | Q28: CAF Presupuesto | R28: Calculada | S28: E2 | T28: Debió iniciar antes del corte y sigue en 0 %. Se mueve el inicio al corte y se conserva la duración.
A29: 51 | B29: Presupuesto | C29: Clasificadores y Catálogos | D29: Clasificador de Enfoque de Género | E29: Reprogramar por avance real | F29: 46302 | G29: 46378 | H29: 46328 | I29: 46402 | J29: =IF(AND(F29<>"",H29<>""),H29-F29,"") -> 26 | K29: =IF(AND(G29<>"",I29<>""),I29-G29,"") -> 24 | L29: 55 | O29: C4 | P29: Media | Q29: CAF Presupuesto | R29: Calculada | S29: E2 | T29: Debió iniciar antes del corte y sigue en 0 %. Se mueve el inicio al corte y se conserva la duración.
A30: 130 | B30: Presupuesto | C30: Clasificadores y Catálogos | D30: Catálogo Actividades (Versión 2) | E30: Reprogramar por avance real | F30: 46307 | G30: 46381 | H30: 46328 | I30: 46402 | J30: =IF(AND(F30<>"",H30<>""),H30-F30,"") -> 21 | K30: =IF(AND(G30<>"",I30<>""),I30-G30,"") -> 21 | L30: 55 | N30: M3 | O30: C4 | P30: Media | Q30: CAF Presupuesto | R30: Calculada | S30: E2 | T30: Debió iniciar antes del corte y sigue en 0 %. Se mueve el inicio al corte y se conserva la duración.
A31: N4 | B31: Presupuesto | C31: Programación | D31: Actualización del MFD de Formulación para proyectos de inversión (Formulación v2) | E31: Nueva tarea | H31: 46569 | I31: 46610 | J31: =IF(AND(F31<>"",H31<>""),H31-F31,"") | K31: =IF(AND(G31<>"",I31<>""),I31-G31,"") | L31: 30 | M31: 150FC; 144FC | O31: C5 | P31: Media | Q31: CAF Presupuesto + CAF Inversiones | R31: Tentativa | S31: E2 | T31: Incorpora al MFD de Formulación (144) el presupuesto por proyecto diseñado en 150, en lugar de adelantar 150.
A32: 186 | B32: Presupuesto | C32: Gestión | D32: Ejecución de gastos de operaciones de endeudamiento | E32: Mover | F32: 46615 | G32: 46675 | H32: 46654 | I32: 46716 | J32: =IF(AND(F32<>"",H32<>""),H32-F32,"") -> 39 | K32: =IF(AND(G32<>"",I32<>""),I32-G32,"") -> 41 | L32: 45 | M32: 270FF; 272FF | O32: C2 | P32: Media | Q32: CAF Presupuesto + CAF Endeudamiento | R32: Calculada | S32: E2 | T32: Debe cerrar junto con las instrucciones de pago de deuda (270 y 272). Conserva su duración.
A33: 250 | B33: Tesorería | C33: Gestión | D33: Traspasos entre cuentas de registros | E33: Reprogramar por avance real | F33: 46296 | G33: 46405 | H33: 46328 | I33: 46435 | J33: =IF(AND(F33<>"",H33<>""),H33-F33,"") -> 32 | K33: =IF(AND(G33<>"",I33<>""),I33-G33,"") -> 30 | L33: 78 | O33: Calidad | P33: Media | Q33: CAF Tesorería | R33: Calculada | S33: E2 | T33: Debió iniciar antes del corte y sigue en 0 %. Se mueve el inicio al corte y se conserva la duración.
A34: 251 | B34: Tesorería | C34: Gestión | D34: Gestión de Documentos Valorados | E34: Reprogramar por avance real | F34: 46286 | G34: 46405 | H34: 46328 | I34: 46447 | J34: =IF(AND(F34<>"",H34<>""),H34-F34,"") -> 42 | K34: =IF(AND(G34<>"",I34<>""),I34-G34,"") -> 42 | L34: 86 | O34: Calidad | P34: Media | Q34: CAF Tesorería | R34: Calculada | S34: E2 | T34: Debió iniciar antes del corte y sigue en 0 %. Se mueve el inicio al corte y se conserva la duración.
A35: 163 | B35: Tesorería | C35: Programación | D35: Asignación de pago – versión 2 (incorpora flujos de caja diarios) | E35: Sin cambio de fechas (pasa a v2) | F35: 46874 | G35: 46904 | H35: 46874 | I35: 46904 | J35: =IF(AND(F35<>"",H35<>""),H35-F35,"") -> 0 | K35: =IF(AND(G35<>"",I35<>""),I35-G35,"") -> 0 | L35: 23 | M35: 162FC | O35: C1 | P35: Media | Q35: CAF Tesorería | R35: Calculada | S35: E2 | T35: Se mantiene en mayo de 2028 como versión completa; ya no bloquea a los pagos de 2027.
A36: N11 | B36: Abastecimiento | C36: Clasificadores y Catálogos | D36: Revisión de catálogos de almacén antes de Logística (versión 2) | E36: Nueva tarea | H36: 47028 | I36: 47053 | J36: =IF(AND(F36<>"",H36<>""),H36-F36,"") | K36: =IF(AND(G36<>"",I36<>""),I36-G36,"") | L36: 20 | N36: 204 | O36: C4 | P36: Baja | Q36: CAF Abastecimiento | R36: Tentativa | S36: E2 | T36: Los catálogos 70–74 se cerraron en 2026 y se usan desde 2029: se revisan antes del diseño de almacén.
A37: H1 | B37: Transversal | C37: Integración | D37: H1 · Clasificadores y Catálogos (versión mínima) disponibles para Programación | E37: Hito | H37: 46402 | I37: 46402 | J37: =IF(AND(F37<>"",H37<>""),H37-F37,"") | K37: =IF(AND(G37<>"",I37<>""),I37-G37,"") | L37: 0 | M37: M3FC | O37: Hitos | P37: Alta | Q37: Coordinación del Proyecto | R37: Calculada | S37: E2 | T37: Hito de aprobación del diseño funcional integrado (MFD).
A38: H2 | B38: Transversal | C38: Integración | D38: H2 · Programación integrada entre sistemas | E38: Hito | H38: 46423 | I38: 46423 | J38: =IF(AND(F38<>"",H38<>""),H38-F38,"") | K38: =IF(AND(G38<>"",I38<>""),I38-G38,"") | L38: 0 | M38: 149FC; 145FC; 169FC; 160FC; 153FC; 138FC | O38: Hitos | P38: Alta | Q38: Coordinación del Proyecto | R38: Calculada | S38: E2 | T38: Hito de aprobación del diseño funcional integrado (MFD).
A39: H3 | B39: Transversal | C39: Integración | D39: H3 · Programación y Gestión articuladas (Apertura y cuotas) | E39: Hito | H39: 46538 | I39: 46538 | J39: =IF(AND(F39<>"",H39<>""),H39-F39,"") | K39: =IF(AND(G39<>"",I39<>""),I39-G39,"") | L39: 0 | M39: 173FC; 175FC; 176FC | O39: Hitos | P39: Alta | Q39: Coordinación del Proyecto | R39: Calculada | S39: E2 | T39: Hito de aprobación del diseño funcional integrado (MFD).
A40: H4 | B40: Transversal | C40: Integración | D40: H4 · Ciclo certificación–compromiso–devengado–pago integrado (diseño) | E40: Hito | H40: 46745 | I40: 46745 | J40: =IF(AND(F40<>"",H40<>""),H40-F40,"") | K40: =IF(AND(G40<>"",I40<>""),I40-G40,"") | L40: 0 | M40: N3FC; 236FC; 234FC; 181FC | O40: Hitos | P40: Alta | Q40: Coordinación del Proyecto | R40: Calculada | S40: E2 | T40: Hito de aprobación del diseño funcional integrado (MFD).
...

Sheet Dependencias
A1: 87 vínculos propuestos. FC = Fin–Comienzo · CC = Comienzo–Comienzo · FF = Fin–Fin. Verificación: 0 conflictos y 0 ciclos con las fechas propuestas.
A2: ID origen | B2: Actividad predecesora | C2: ID destino | D2: Actividad sucesora | E2: Tipo de relación | F2: Desfase (días háb.) | G2: Holgura verificada (días háb.) | H2: Cumple con las fechas propuestas | I2: Justificación | J2: Validación requerida | K2: Ref. diagnóstico
A3: 161 | B3: Flujos de caja proyectados mensual, trimestrales, anuales (estimación de egresos) | C3: N1 | D3: Asignación de pago – versión mínima (cuota de pago v1 con reglas vigentes) | E3: FC | F3: 0 | G3: 9 | H3: Sí | I3: La cuota v1 se calcula con los flujos de caja proyectados. | J3: CAF Tesorería | K3: D1
A4: N1 | B4: Asignación de pago – versión mínima (cuota de pago v1 con reglas vigentes) | C4: 236 | D4: Gestión de pagos con medio de Pago Entre CUT | E4: FC | F4: 0 | G4: 9 | H4: Sí | I4: Los pagos entre CUT requieren la cuota de pago. | J4: CAF Tesorería | K4: D1
A5: N1 | B5: Asignación de pago – versión mínima (cuota de pago v1 con reglas vigentes) | C5: 234 | D5: Operativización del Pago con Entidades Financieras y confirmación de la recepción de fondos (pagado) | E5: FC | F5: 0 | G5: 12 | H5: Sí | I5: La operativización del pago requiere la cuota de pago. | J5: CAF Tesorería | K5: D1
A6: N1 | B6: Asignación de pago – versión mínima (cuota de pago v1 con reglas vigentes) | C6: 235 | D6: Gestion de Pago por medio de pago transferencia | E6: FC | F6: 0 | G6: 204 | H6: Sí | I6: El pago por transferencia requiere la cuota de pago. | J6: CAF Tesorería | K6: D1
A7: N1 | B7: Asignación de pago – versión mínima (cuota de pago v1 con reglas vigentes) | C7: 233 | D7: Gestión de Pago por Medio de pago Cheque | E7: FC | F7: 0 | G7: 77 | H7: Sí | I7: El pago con cheque requiere la cuota de pago. | J7: CAF Tesorería | K7: D1
A8: 161 | B8: Flujos de caja proyectados mensual, trimestrales, anuales (estimación de egresos) | C8: 162 | D8: Flujos de Caja Diarios (Insumo para la asignación de Cuotas de Pago) | E8: FC | F8: 0 | G8: 226 | H8: Sí | I8: Los flujos diarios parten de los proyectados. | J8: CAF Tesorería | K8: D1
A9: 162 | B9: Flujos de Caja Diarios (Insumo para la asignación de Cuotas de Pago) | C9: 163 | D9: Asignación de pago – versión 2 (incorpora flujos de caja diarios) | E9: FC | F9: 0 | G9: 0 | H9: Sí | I9: La cuota v2 incorpora los flujos de caja diarios. | J9: CAF Tesorería | K9: D1
A10: N2 | B10: Certificación y modelo común de datos del gasto (certificación, compromiso y devengado) | C10: 195 | D10: Actuaciones preparatorias | E10: FF | F10: 0 | G10: 107 | H10: Sí | I10: Las Actuaciones preparatorias no cierran su MFD sin la certificación de crédito. | J10: CAF Presupuesto y CAF Abastecimiento | K10: D23 (nueva)
A11: N2 | B11: Certificación y modelo común de datos del gasto (certificación, compromiso y devengado) | C11: 181 | D11: Compromiso de gastos de bienes, servicios y obras | E11: FC | F11: 0 | G11: 62 | H11: Sí | I11: El compromiso usa el modelo común de datos del gasto. | J11: CAF Presupuesto | K11: D2
A12: N2 | B12: Certificación y modelo común de datos del gasto (certificación, compromiso y devengado) | C12: 182 | D12: Ejecución de gastos de gestión fiscal | E12: FC | F12: 0 | G12: 52 | H12: Sí | I12: La ejecución de gestión fiscal usa el modelo común de datos. | J12: CAF Presupuesto | K12: D2
A13: N2 | B13: Certificación y modelo común de datos del gasto (certificación, compromiso y devengado) | C13: 236 | D13: Gestión de pagos con medio de Pago Entre CUT | E13: FC | F13: 0 | G13: 52 | H13: Sí | I13: Los pagos usan el modelo del devengado. | J13: CAF Tesorería y CAF Presupuesto | K13: D24 (nueva)
A14: N2 | B14: Certificación y modelo común de datos del gasto (certificación, compromiso y devengado) | C14: 234 | D14: Operativización del Pago con Entidades Financieras y confirmación de la recepción de fondos (pagado) | E14: FC | F14: 0 | G14: 55 | H14: Sí | I14: Los pagos usan el modelo del devengado. | J14: CAF Tesorería y CAF Presupuesto | K14: D24 (nueva)
... A89: 296 | B89: Registro manual de cronograma de servicio | C89: H7 | D89: H7 · Integración funcional completa de los siete sistemas (diseño) | E89: FC | F89: 0 | G89: 0 | H89: Sí | I89: Hito de integración. | J89: Coordinación | K89: H7

Sheet Importar a Project
A1: Para la PMO: actualizar las filas con Id y crear las que solo tienen código bajo la tarea resumen indicada. Al crearlas, reemplazar los códigos N#, M# y H# de «Predecesoras» por los Id que asigne Project. Alternativa: abrir el archivo XML entregado, que ya trae todo cargado (columna «Id en el XML»).
A2: Id (existente) | B2: Código | C2: Id en el XML | D2: Nombre | E2: Tarea resumen sugerida (Id) | F2: Comienzo | G2: Fin | H2: Duración | I2: Hito | J2: Predecesoras | K2: Modo de programación | L2: Notas
A3: 46 | B3: 46 | C3: 46 | D3: Catálogo de relación Estructura Funcional Programática - EFP | F3: 45980 | G3: 46339 | H3: 142 días | I3: No | K3: Manual (validar antes de pasar a automático) | L3: Vencida al 99 %. Se fija el cierre formal del MFD para que pueda usarse como insumo.
A4: 62 | B4: 62 | C4: 62 | D4: Gestor de responsables (responsables por equipo) | F4: 45999 | G4: 46339 | H4: 118 días | I4: No | K4: Manual (validar antes de pasar a automático) | L4: Vencida al 99 %. Se fija el cierre formal del MFD para que pueda usarse como insumo.
A5: 25 | B5: 25 | C5: 25 | D5: Catálogo de Finalidades / Sub actividad | F5: 46063 | G5: 46339 | H5: 82 días | I5: No | K5: Manual (validar antes de pasar a automático) | L5: Vencida al 99 %. Se fija el cierre formal del MFD para que pueda usarse como insumo.
A6: 59 | B6: 59 | C6: 59 | D6: Catálogo de equipo de trabajo | F6: 46118 | G6: 46339 | H6: 106 días | I6: No | K6: Manual (validar antes de pasar a automático) | L6: Vencida al 99 %. Se fija el cierre formal del MFD para que pueda usarse como insumo.
A7: 60 | B7: 60 | C7: 60 | D7: Catálogo criterio de conformación | F7: 46118 | G7: 46339 | H7: 106 días | I7: No | K7: Manual (validar antes de pasar a automático) | L7: Vencida al 99 %. Se fija el cierre formal del MFD para que pueda usarse como insumo.
A8: 147 | B8: 147 | C8: 147 | D8: Elaboración de la PMI y PMIE | F8: 46266 | G8: 46360 | H8: 65 días | I8: No | K8: Manual (validar antes de pasar a automático) | L8: Sale de StandBy el 2026-11-02; le quedan unos 25 días (38 % de 65). Es predecesora de 149.
A9: 63 | B9: 63 | C9: 63 | D9: Catálogo de Grupo de Trabajo | F9: 46266 | G9: 46339 | H9: 22 días | I9: No | K9: Manual (validar antes de pasar a automático) | L9: Vencida al 99 %. Se fija el cierre formal del MFD para que pueda usarse como insumo.
A10: 48 | B10: 48 | C10: 48 | D10: Clasificador de Recursos hidricos y saneamiento | F10: 46328 | G10: 46419 | H10: 66 días | I10: No | K10: Manual (validar antes de pasar a automático) | L10: Debió iniciar antes del corte y sigue en 0 %. Se mueve el inicio al corte y se conserva la duración.
A11: 51 | B11: 51 | C11: 51 | D11: Clasificador de Enfoque de Género | F11: 46328 | G11: 46402 | H11: 55 días | I11: No | K11: Manual (validar antes de pasar a automático) | L11: Debió iniciar antes del corte y sigue en 0 %. Se mueve el inicio al corte y se conserva la duración.
A12: 130 | B12: 130 | C12: 130 | D12: Catálogo Actividades (Versión 2) | F12: 46328 | G12: 46402 | H12: 55 días | I12: No | K12: Manual (validar antes de pasar a automático) | L12: Debió iniciar antes del corte y sigue en 0 %. Se mueve el inicio al corte y se conserva la duración.
A13: 250 | B13: 250 | C13: 250 | D13: Traspasos entre cuentas de registros | F13: 46328 | G13: 46435 | H13: 78 días | I13: No | K13: Manual (validar antes de pasar a automático) | L13: Debió iniciar antes del corte y sigue en 0 %. Se mueve el inicio al corte y se conserva la duración.
A14: 251 | B14: 251 | C14: 251 | D14: Gestión de Documentos Valorados | F14: 46328 | G14: 46447 | H14: 86 días | I14: No | K14: Manual (validar antes de pasar a automático) | L14: Debió iniciar antes del corte y sigue en 0 %. Se mueve el inicio al corte y se conserva la duración.
A15: 81 | B15: 81 | C15: 81 | D15: Catálogo GFRH por definir (antes «<Tarea nueva>») | F15: 46328 | G15: 46414 | H15: 63 días | I15: No | K15: Manual (validar antes de pasar a automático) | L15: Debió iniciar antes del corte y sigue en 0 %. Se mueve el inicio al corte y se conserva la duración.
B16: M5 | C16: 390 | D16: Hito: estructura del Catálogo relacional Deuda–Inversión aprobada | E16: 15 | F16: 46356 | G16: 46356 | H16: 0 días | I16: Sí | J16: 82CC+20 días | K16: Manual (validar antes de pasar a automático) | L16: Entrega parcial de 82 que necesitan 149 y 256.
A17: 149 | B17: 149 | C17: 149 | D17: Registro estructura del Proyecto y su relación con la Estructura Presupuestaria | F17: 46363 | G17: 46423 | H17: 45 días | I17: No | J17: 147FC; M5FC | K17: Manual (validar antes de pasar a automático) | L17: Empieza cuando la PMI esté aprobada (147). Conserva su duración.
B18: M3 | C18: 388 | D18: Hito: versión mínima de catálogos para Programación (estructura aprobada) | E18: 15 | F18: 46402 | G18: 46402 | H18: 0 días | I18: Sí | J18: 46FC; 65FC; 66FC; 129FC; 130FC; 131FC; 128CC+40 días; 132CC+40 días | K18: Manual (validar antes de pasar a automático) | L18: Estructura (atributos y relaciones) aprobada de 46, 47, 65, 66 y 128–132. El poblado completo puede seguir después.
B19: M4 | C19: 389 | D19: Hito: estructura de metas v1 aprobada (entrega parcial de 140) | E19: 135 | F19: 46402 | G19: 46402 | H19: 0 días | I19: Sí | J19: 140CC+30 días | K19: Manual (validar antes de pasar a automático) | L19: La Formulación (144) cierra su MFD con la estructura de metas; el Administrador de Metas (140) se completa para la Apertura.
B20: M8 | C20: 391 | D20: Hito: proyección preliminar del servicio de deuda para la Formulación | E20: 164 | F20: 46402 | G20: 46402 | H20: 0 días | I20: Sí | J20: 168FF-10 días | K20: Manual (validar antes de pasar a automático) | L20: Versión preliminar de 167/169 para que la Formulación (144) cierre con el dato de deuda. Se mantiene la restricción de 165 y 170.
B21: M9 | C21: 392 | D21: Hito: estimación preliminar de ingresos por OOC, RO y RD para la Formulación | E21: 158 | F21: 46402 | G21: 46402 | H21: 0 días | I21: Sí | J21: 160FF-10 días | K21: Manual (validar antes de pasar a automático) | L21: Versión preliminar de 160 para la Formulación (144).
B22: H1 | C22: 395 | D22: H1 · Clasificadores y Catálogos (versión mínima) disponibles para Programación | E22: 2 | F22: 46402 | G22: 46402 | H22: 0 días | I22: Sí | J22: M3FC | K22: Manual (validar antes de pasar a automático) | L22: Hito de aprobación del diseño funcional integrado (MFD).
B23: N2 | C23: 377 | D23: Certificación y modelo común de datos del gasto (certificación, compromiso y devengado) | E23: 180 | F23: 46419 | G23: 46479 | H23: 45 días | I23: No | K23: Manual (validar antes de pasar a automático) | L23: Las Actuaciones preparatorias (195) requieren la certificación de crédito, y Pagos (234, 236) requiere el modelo del devengado. Duración igual a la de la fila 181 (45 días).
B24: H2 | C24: 396 | D24: H2 · Programación integrada entre sistemas | E24: 2 | F24: 46423 | G24: 46423 | H24: 0 días | I24: Sí | J24: 149FC; 145FC; 169FC; 160FC; 153FC; 138FC | K24: Manual (validar antes de pasar a automático) | L24: Hito de aprobación del diseño funcional integrado (MFD).
B25: N1 | C25: 376 | D25: Asignación de pago – versión mínima (cuota de pago v1 con reglas vigentes) | E25: 158 | F25: 46510 | G25: 46540 | H25: 23 días | I25: No | J25: 161FC | K25: Manual (validar antes de pasar a automático) | L25: Habilita los pagos que se diseñan desde el 16/06/2027 (236) usando los flujos de caja proyectados (161). Se conserva la duración de la fila 163 (23 días).
B26: H3 | C26: 397 | D26: H3 · Programación y Gestión articuladas (Apertura y cuotas) | E26: 2 | F26: 46538 | G26: 46538 | H26: 0 días | I26: Sí | J26: 173FC; 175FC; 176FC | K26: Manual (validar antes de pasar a automático) | L26: Hito de aprobación del diseño funcional integrado (MFD).
B27: M1 | C27: 386 | D27: Hito: interfaz de contrato, OC y OS aprobada (entrega parcial de 196) | E27: 194 | F27: 46567 | G27: 46567 | H27: 0 días | I27: Sí | J27: 196CC+32 días | K27: Manual (validar antes de pasar a automático) | L27: Entrega parcial de 196: estructura de datos del contrato y de la orden, suficiente para diseñar el compromiso.
A28: 181 | B28: 181 | C28: 181 | D28: Compromiso de gastos de bienes, servicios y obras | F28: 46568 | G28: 46630 | H28: 45 días | I28: No | J28: N2FC; M1FC; 175FC; 176FC | K28: Manual (validar antes de pasar a automático) | L28: Se diseña con la interfaz de la orden (M1) aprobada. Conserva su duración (45 días).
B29: N4 | C29: 382 | D29: Actualización del MFD de Formulación para proyectos de inversión (Formulación v2) | E29: 143 | F29: 46569 | G29: 46610 | H29: 30 días | I29: No | J29: 150FC; 144FC | K29: Manual (validar antes de pasar a automático) | L29: Incorpora al MFD de Formulación (144) el presupuesto por proyecto diseñado en 150, en lugar de adelantar 150.
B30: M6 | C30: 393 | D30: Hito: interfaz planilla–compromiso–devengado–pago validada con GFRH | E30: 180 | F30: 46610 | G30: 46610 | H30: 0 días | I30: Sí | J30: 182CC+40 días | K30: Manual (validar antes de pasar a automático) | L30: GFRH concluyó su diseño en 2026; se valida su interfaz dentro de la Ejecución de gestión fiscal (182).
A31: 186 | B31: 186 | C31: 186 | D31: Ejecución de gastos de operaciones de endeudamiento | F31: 46654 | G31: 46716 | H31: 45 días | I31: No | J31: 270FF; 272FF | K31: Manual (validar antes de pasar a automático) | L31: Debe cerrar junto con las instrucciones de pago de deuda (270 y 272). Conserva su duración.
B32: M2 | C32: 387 | D32: Hito: interfaz de Conformidad aprobada (entrega parcial de 197) | E32: 194 | F32: 46689 | G32: 46689 | H32: 0 días | I32: Sí | J32: 197CC+42 días | K32: Manual (validar antes de pasar a automático) | L32: Entrega parcial de 197: datos de la conformidad que habilitan el devengado.
B33: N3 | C33: 378 | D33: Devengado de gastos de bienes, servicios y obras | E33: 180 | F33: 46692 | G33: 46745 | H33: 40 días | I33: No | J33: M2FC; 181FC | K33: Manual (validar antes de pasar a automático) | L33: Separa el devengado del compromiso para alinearlo con la Conformidad (197).
B34: H4 | C34: 398 | D34: H4 · Ciclo certificación–compromiso–devengado–pago integrado (diseño) | E34: 2 | F34: 46745 | G34: 46745 | H34: 0 días | I34: Sí | J34: N3FC; 236FC; 234FC; 181FC | K34: Manual (validar antes de pasar a automático) | L34: Hito de aprobación del diseño funcional integrado (MFD).
B35: N5 | C35: 379 | D35: Adecuación de cierres y estados presupuestales a las fuentes AFSP | E35: 353 | F35: 46748 | G35: 46801 | H35: 40 días | I35: No | J35: N3FC | K35: Manual (validar antes de pasar a automático) | L35: Escenario A: los cierres de 2026–2027 usan el SIAF-SP (integración 344 concluida). Esta tarea adapta 355, 358, 359 y 360 cuando exista la ejecución AFSP, antes de la Cuenta General (363).
A36: 163 | B36: 163 | C36: 163 | D36: Asignación de pago – versión 2 (incorpora flujos de caja diarios) | F36: 46874 | G36: 46904 | H36: 23 días | I36: No | J36: 162FC | K36: Manual (validar antes de pasar a automático) | L36: Se mantiene en mayo de 2028 como versión completa; ya no bloquea a los pagos de 2027.
B37: H6 | C37: 400 | D37: H6 · Gestión y Evaluación articuladas | E37: 2 | F37: 47012 | G37: 47012 | H37: 0 días | I37: Sí | J37: 363FC; 373FC; 352FC | K37: Manual (validar antes de pasar a automático) | L37: Hito de aprobación del diseño funcional integrado (MFD).
B38: H5 | C38: 399 | D38: H5 · Gestión y Contabilidad articuladas (motor contable v2) | E38: 2 | F38: 47018 | G38: 47018 | H38: 0 días | I38: Sí | J38: 347FC | K38: Manual (validar antes de pasar a automático) | L38: Hito de aprobación del diseño funcional integrado (MFD).
B39: N11 | C39: 384 | D39: Revisión de catálogos de almacén antes de Logística (versión 2) | E39: 15 | F39: 47028 | G39: 47053 | H39: 20 días | I39: No | K39: Manual (validar antes de pasar a automático) | L39: Los catálogos 70–74 se cerraron en 2026 y se usan desde 2029: se revisan antes del diseño de almacén.
B40: N6 | C40: 380 | D40: Actualización 3 de Catálogo de Eventos y Motor de Contabilización | E40: 342 | F40: 47210 | G40: 47270 | H40: 45 días | I40: No | J40: 347FC | K40: Manual (validar antes de pasar a automático) | L40: Cubre los eventos de Endeudamiento etapa 2 y de Abastecimiento diseñados entre oct 2028 y mar 2029.
...

Sheet Validación diagnóstico
A1: Revisión crítica de las 22 dependencias del diagnóstico y 2 nuevas (D23, D24).
A2: Dependencia | B2: Descripción | C2: ¿Obligatoria? | D2: Naturaleza | E2: Tratamiento | F2: Resultado | G2: Nota
A3: D1 | B3: Cuota de pago (162–163) → Gestión de pagos (233–236) | C3: Sí (operación y diseño) | D3: Secuencia real | E3: Entrega parcial (N1) + división v1/v2 | F3: Se corrige | G3: Fecha requerida 16/06/2027; brecha 350 días.
A4: D2 | B4: Contrato, OC y OS (196) → compromiso de bienes y servicios (181) | C4: Sí | D4: Secuencia real | E4: Entrega parcial (M1) + mover 181 +29 días | F4: Se mantiene
A5: D3 | B5: Conformidad (197) → devengado de bienes y servicios | C5: Sí | D5: Secuencia real | E5: Dividir 181 + entrega parcial (M2) + nueva N3 | F5: Se mantiene
A6: D4 | B6: Ejecución presupuestaria → Estados presupuestales y cierre (359–360) | C6: Depende de la fuente | D6: Depende de decisión | E6: Escenario A + adecuación N5 | F6: Se corrige | G6: Rebajada: transición con SIAF-SP.
A7: D5 | B7: Gestión (ejecución, pagos, deuda) → Estados financieros (355, 358) | C7: Depende de la fuente | D7: Depende de decisión | E7: Escenario A + adecuación N5 | F7: Se corrige
A8: D6 | B8: Procesos 2028–2029 → motor contable (347) | C8: Sí | D8: Secuencia real | E8: Nuevas actualizaciones 3 y 4 (N6, N7) | F8: Se mantiene
A9: D7 | B9: Formulación por proyecto (150) → Formulación (144) | C9: Sí (diseño) | D9: Secuencia real de diseño | E9: Nueva Formulación v2 (N4); no se adelanta 150 | F9: Se corrige | G9: Se evita comprimir 150.
A10: D8 | B10: Administrador de Metas (140) → Formulación (144) | C10: Parcial | D10: Solapamiento de diseño | E10: Entrega parcial (M4) | F10: Se corrige | G10: Se retira la compresión de 140.
A11: D9 | B11: Clasificadores temáticos (49–50) → Formulación (144) | C11: No para el MFD | D11: Solapamiento de diseño | E11: Aplicar desde la Formulación 2028 (DEC-6) | F11: Se corrige
A12: D10 | B12: Catálogos v2 y relación actividad–finalidad (128–132) → Formulación (144) | C12: Parcial (estructura) | D12: Solapamiento de diseño | E12: Entrega parcial (M3) | F12: Se corrige
A13: D11 | B13: PMI y PMIE (147, StandBy) → Registro de proyectos (149) | C13: Sí | D13: Secuencia real | E13: Reactivar 147 y mover 149 +6 días | F13: Se mantiene | G13: Pendiente de DEC-4.
A14: D12 | B14: Instrucciones de pago de deuda (270, 272) → ejecución de gastos de deuda (186) | C14: Sí | D14: Secuencia real | E14: Mover 186 +41 días (FF) | F14: Se mantiene
A15: D13 | B15: Ejecución presupuestaria → Seguimiento de metas (366–369) | C15: Parcial | D15: Solapamiento viable | E15: Vínculo FF | F15: Se mantiene
A16: D14 | B16: Catálogo relacional Deuda–Inversión (82) → 149 y 256 | C16: Parcial (estructura) | D16: Secuencia real | E16: Entrega parcial (M5) | F16: Se corrige | G16: Se retira la compresión de 82.
A17: D15 | B17: Gestión administrativa de inversiones (188) → Seguimiento (350) | C17: Parcial | D17: Solapamiento viable | E17: Vínculo FF | F17: Se mantiene
A18: D16 | B18: CMN (153) y PAC (155) → Actuaciones preparatorias (195) | C18: Sí | D18: Solapamiento viable | E18: Vínculos FC y FF | F18: Se mantiene
A19: D17 | B19: Proyección de deuda (167, 169) → Formulación (144) | C19: Parcial | D19: Solapamiento de diseño | E19: Entrega parcial (M8) | F19: Se mantiene
A20: D18 | B20: Recursos OOC, RO y RD (160) → Formulación (144) | C20: Parcial | D20: Solapamiento de diseño | E20: Entrega parcial (M9) | F20: Se mantiene
A21: D19 | B21: Catálogos de consolidación (108–109) → Consolidación (356–357) | C21: Sí | D21: Solapamiento viable | E21: Vínculo FC −5 días | F21: Se corrige | G21: Se retira el ajuste 11.
A22: D20 | B22: Cuotas de compromiso (175–176) → compromiso (181) | C22: Sí | D22: Secuencia correcta | E22: Vínculo FC | F22: Se mantiene | G22: Holgura sube a 21 días.
A23: D21 | B23: Formulación y Aprobación (144–145) → Apertura (173) | C23: Sí | D23: Secuencia correcta | E23: Vínculo FC | F23: Se mantiene
A24: D22 | B24: Planillas GFRH (216) → gestión fiscal (182) y pagos | C24: Sí | D24: Interfaz no validada | E24: Hito de validación (M6) | F24: Se mantiene
A25: D23 | B25: Certificación de crédito → Actuaciones preparatorias (195) | C25: Sí | D25: Secuencia real (nueva) | E25: Nueva N2 (FF con 195) | F25: Nueva | G25: No estaba en el diagnóstico.
A26: D24 | B26: Modelo del devengado → Pagos (234, 236) | C26: Sí | D26: Secuencia real (nueva) | E26: Nueva N2 (FC con 234 y 236) | F26: Nueva | G26: No estaba en el diagnóstico.
A29: Revisión de los 12 ajustes del diagnóstico
A30: Ajuste | B30: Ajuste original | C30: Decisión | D30: Motivo y reemplazo
A31: 1 | B31: Adelantar 162–163 a ene–abr 2027 (−422 días) | C31: Se modifica | D31: Cuota v1 (N1) en may 2027; 162–163 se mantienen como v2.
A32: 2 | B32: Dividir 181 en compromiso y devengado (+125/+223) | C32: Se modifica | D32: División en tres (N2, 181, N3) con entregas parciales M1 y M2; compromiso solo +29 días.
A33: 3 | B33: Adelantar el Administrador de Metas (−66) | C33: Se retira | D33: Compresión sin capacidad verificada. Se reemplaza por M4.
A34: 4 | B34: Adelantar clasificadores temáticos (−48/−75) | C34: Se retira | D34: Se aplican desde la Formulación 2028 (DEC-6).
A35: 5 | B35: Adelantar catálogos v2 al 15/01/2027 | C35: Se modifica | D35: Solo la estructura (M3); el poblado sigue su fecha.
A36: 6 | B36: Mover cierres contables +418 días | C36: Se modifica | D36: Solo en el escenario B. Se recomienda el A con la adecuación N5.
A37: 7 | B37: Nueva actualización 3 del motor contable | C37: Se modifica | D37: Dos actualizaciones (N6 y N7) para cubrir hasta dic 2029.
A38: 8 | B38: Versión preliminar de deuda e ingresos | C38: Se mantiene | D38: Hitos M8 y M9; se conservan las restricciones de 165 y 170.
A39: 9 | B39: Adelantar el catálogo 82 (−34) | C39: Se modifica | D39: Entrega parcial M5 al 30/11/2026, sin comprimir 82.
A40: 10 | B40: Mover 186 +41 días | C40: Se mantiene | D40: Vínculo FF con 269.
A41: 11 | B41: Adelantar 108–109 (−13) | C41: Se retira | D41: Solapamiento aceptado con vínculo FC −5 días.
A42: 12 | B42: Decidir PMI y Formulación por proyecto | C42: Se mantiene | D42: DEC-4 y nueva Formulación v2 (N4).
...

Sheet Alternativas
A1: Evaluación de alternativas A, B y C por caso. Se prioriza la integridad funcional, no el menor movimiento de fechas.
A2: Caso | B2: Alt. | C2: Descripción | D2: Integración funcional | E2: Impacto en otros sistemas | F2: Variación del cronograma | G2: Riesgo de retrabajo | H2: Complejidad | I2: Recursos adicionales | J2: Viabilidad | K2: Efecto en hitos | L2: Selección | M2: Por qué
A3: Caso 1 · Tesorería | B3: A | C3: Adelantar 162 y 163 completos a ene–abr 2027 | D3: Alta | E3: Bajo | F3: Alta (−422 d) | G3: Bajo | H3: Media | I3: Altos | J3: Baja | K3: Neutro
A4: Caso 1 · Tesorería | B4: B | C4: Cuota de pago v1 mínima (N1, may 2027) y v2 completa en may 2028 | D4: Alta | E4: Bajo | F4: Baja (nueva tarea) | G4: Medio | H4: Baja | I4: Bajos | J4: Alta | K4: Favorable (H4) | L4: Recomendada | M4: Habilita los pagos de 2027 con una regla mínima, sin comprimir Tesorería ni retrasar el ciclo financiero.
A5: Caso 1 · Tesorería | B5: C | C5: Retrasar los pagos (233–236) hasta después de may 2028 | D5: Media | E5: Alto | F5: Alta (+350 d) | G5: Bajo | H5: Baja | I5: Nulos | J5: Media | K5: Desfavorable
A6: Caso 2 · Abastecimiento – Presupuesto | B6: A | C6: Adelantar contrato/OC/OS (196) y Conformidad (197) | D6: Alta | E6: Medio | F6: Alta | G6: Bajo | H6: Alta | I6: Altos | J6: Baja (dependen de 195) | K6: Neutro
A7: Caso 2 · Abastecimiento – Presupuesto | B7: B | C7: Dividir 181 en certificación, compromiso y devengado, con entregas parciales M1 y M2 | D7: Alta | E7: Bajo | F7: Baja (+29 d) | G7: Bajo | H7: Media | I7: Medios | J7: Alta | K7: Favorable (H4) | L7: Recomendada | M7: Ordena el ciclo certificación → compromiso → devengado → pago con la menor variación, y agrega la certificación que faltaba.
A8: Caso 2 · Abastecimiento – Presupuesto | B8: C | C8: Mover 181 completa después de 197 | D8: Media | E8: Alto | F8: Alta (+160 d) | G8: Bajo | H8: Baja | I8: Bajos | J8: Media | K8: Desfavorable
A9: Caso 3 · Contabilidad – Gestión – Evaluación | B9: A | C9: Usar el SIAF-SP como fuente de transición y adecuar cierres (N5) en 2028 | D9: Media-alta | E9: Bajo | F9: Nula en 2026–2027 | G9: Medio | H9: Baja | I9: Bajos | J9: Alta | K9: Neutro | L9: Recomendada | M9: Es coherente con lo ya construido (344, 354, 361, 362 terminados) y evita retrasar la Cuenta General.
A10: Caso 3 · Contabilidad – Gestión – Evaluación | B10: B | C10: Usar solo los nuevos sistemas AFSP: mover 355, 358, 359 y 360 después de la ejecución | D10: Alta | E10: Alto (CGR, EFP) | F10: Alta (+418 d) | G10: Bajo | H10: Media | I10: Medios | J10: Media | K10: Desfavorable (H6)
A11: Caso 4 · Clasificadores y Catálogos | B11: A | C11: Adelantar las fechas de fin de los catálogos | D11: Alta | E11: Bajo | F11: Media | G11: Bajo | H11: Media | I11: Altos | J11: Baja | K11: Neutro
A12: Caso 4 · Clasificadores y Catálogos | B12: B | C12: Versión mínima (estructura) al 15/01/2027 (M3), versión completa en su fecha y actualizaciones por ciclo | D12: Alta | E12: Bajo | F12: Nula | G12: Medio | H12: Baja | I12: Bajos | J12: Alta | K12: Favorable (H1) | L12: Recomendada | M12: La Formulación necesita la estructura, no el poblado completo. No exige comprimir trabajo.
A13: Caso 5 · Inversiones – Presupuesto | B13: A | C13: Reactivar PMI (147) ya, mover 149 +6 días y agregar Formulación v2 (N4) | D13: Alta | E13: Bajo | F13: Baja | G13: Medio | H13: Baja | I13: Bajos | J13: Alta | K13: Favorable (H2) | L13: Recomendada | M13: Resuelve la cadena PMI → registro → formulación con el menor movimiento; la Formulación v2 integra el detalle por proyecto.
A14: Caso 5 · Inversiones – Presupuesto | B14: B | C14: Mantener StandBy y mover 149, 150 y N4 por cada mes de espera | D14: Media | E14: Medio | F14: Variable | G14: Medio | H14: Baja | I14: Nulos | J14: Media | K14: Desfavorable
A15: Caso 5 · Inversiones – Presupuesto | B15: C | C15: Adelantar 150 para que se diseñe junto con 144 | D15: Alta | E15: Medio | F15: Media | G15: Bajo | H15: Alta | I15: Altos | J15: Baja (149 no termina antes) | K15: Neutro
A16: Caso 6 · Endeudamiento – Contabilidad | B16: A | C16: Una sola actualización final del motor en 2029 | D16: Media | E16: Bajo | F16: Baja | G16: Alto | H16: Baja | I16: Bajos | J16: Media | K16: Neutro
A17: Caso 6 · Endeudamiento – Contabilidad | B17: B | C17: Dos actualizaciones: N6 (abr–jun 2029) y N7 (oct–dic 2029, FF con 296) | D17: Alta | E17: Bajo | F17: Baja | G17: Bajo | H17: Media | I17: Medios | J17: Alta | K17: Favorable (H5, H7) | L17: Recomendada | M17: Reduce el retrabajo al incorporar los eventos de deuda por bloques, a medida que se diseñan.
A18: Caso 7 · Evaluación transversal | B18: A | C18: Crear un módulo de Evaluación por sistema | D18: Alta | E18: Alto | F18: Alta | G18: Bajo | H18: Alta | I18: Altos | J18: Baja | K18: Desfavorable
A19: Caso 7 · Evaluación transversal | B19: B | C19: Evaluar a través de Presupuesto, Inversiones y Contabilidad, con una validación final (N10) | D19: Alta | E19: Bajo | F19: Baja | G19: Medio | H19: Baja | I19: Bajos | J19: Alta | K19: Favorable (H6, H7) | L19: Recomendada | M19: Los datos de los siete sistemas ya llegan a Evaluación vía la contabilidad (CGR, EFP) y la ejecución presupuestaria.

Sheet Escenarios
A1: Comparación de escenarios. «No verificable» indica que el .mpp no tiene datos (recursos, construcción) para calcularlo.
A2: Criterio | B2: Escenario 1 – Conservador | C2: Escenario 2 – Integración optimizada (recomendado) | D2: Escenario 3 – Integración prioritaria
A3: Fecha estimada de cierre del diseño | B3: 28/12/2029 | C3: 28/12/2029 | D3: No verificable: posterior a 28/12/2029 si no se suman recursos
A4: Dependencias resueltas (de 24) | B4: 7 resueltas · 5 condicionadas · 4 pendientes de decisión · 8 sin resolver | C4: 8 resueltas · 12 condicionadas · 4 pendientes de decisión · 0 sin resolver | D4: 9 resueltas · 15 condicionadas · 0 pendientes · 0 sin resolver
A5: Alertas críticas pendientes | B5: 2 (mitigadas solo con hitos) | C5: 0 (condicionadas a validación de capacidad) | D5: 0
A6: Actividades reprogramadas | B6: 12 (solo actualización por avance real) | C6: 16 con cambio de fecha + 9 nuevas + 15 hitos | D6: Más de 22 con cambio de fecha + diferimiento de procesos no críticos
A7: Impacto en recursos | B7: Bajo | C7: Medio: +1 a +2 actividades simultáneas en Presupuesto (feb–abr 2027) y Tesorería (may–jun 2027) | D7: Alto: Tesorería y Contabilidad en paralelo en 2027
A8: Riesgo residual | B8: Alto | C8: Medio | D8: Medio (bajo funcional, alto de plazo)
A9: Viabilidad | B9: Alta | C9: Media-alta (condicionada) | D9: Baja sin recursos adicionales

Sheet Hitos de integración
A1: Hitos de aprobación del diseño funcional integrado. No se declara alcanzado un hito sin el acta o evidencia del criterio de aceptación.
A2: Hito | B2: Descripción | C2: Sistemas involucrados | D2: Entregables necesarios | E2: Fecha objetivo (diseño) | F2: Criterio de aceptación | G2: Responsable propuesto | H2: Hito de software y puesta en uso
A3: H1 | B3: Clasificadores y Catálogos (versión mínima) disponibles para Programación | C3: Presupuesto, Endeudamiento, Tesorería, Inversiones | D3: M3 (estructura de 46, 47, 65, 66, 128–132); M5 | E3: 46402 | F3: Estructuras aprobadas por la DG y cargadas en el Administrador de Catálogos (sin poblado completo) | G3: CAF Presupuesto | H3: No verificable: el .mpp no programa la construcción (C3)
A4: H2 | B4: Programación integrada entre sistemas | C4: Presupuesto, Inversiones, Endeudamiento, Tesorería, Abastecimiento | D4: 138, 144, 145, 149, 153, 160, 169; M4, M8, M9 | E4: 46423 | F4: MFD de Formulación con metas, deuda, ingresos y estructura de proyectos referenciados | G4: CAF Presupuesto + Coordinación | H4: No verificable: el .mpp no programa la construcción (C3)
A5: H3 | B5: Programación y Gestión articuladas | C5: Presupuesto, Inversiones | D5: 173, 175, 176 | E5: 46538 | F5: Apertura y cuotas de compromiso diseñadas sobre el presupuesto aprobado | G5: CAF Presupuesto | H5: No verificable: el .mpp no programa la construcción (C3)
A6: H4 | B6: Ciclo certificación–compromiso–devengado–pago integrado | C6: Presupuesto, Abastecimiento, Tesorería, GFRH | D6: N2, M1, 181, M2, N3, N1, 234, 236, M6 | E6: 46745 | F6: Modelo común de datos del gasto aprobado por los cuatro CAF; trazabilidad de la orden al pago | G6: Mesa de integración interCAF | H6: No verificable: el .mpp no programa la construcción (C3)
A7: H5 | B7: Gestión y Contabilidad articuladas (motor contable v2) | C7: Contabilidad y los seis sistemas de Gestión | D7: 346, 347 | E7: 47018 | F7: Catálogo de Eventos con los eventos de ejecución, pagos y deuda etapa 1 | G7: CAF Contabilidad | H7: No verificable: el .mpp no programa la construcción (C3)
A8: H6 | B8: Gestión y Evaluación articuladas | C8: Presupuesto, Inversiones, Contabilidad | D8: 363, 373, 352, N5 | E8: 47012 | F8: Evaluación presupuestaria, de inversiones y Cuenta General diseñadas con las fuentes AFSP | G8: CAF Contabilidad + CAF Presupuesto | H8: No verificable: el .mpp no programa la construcción (C3)
A9: H7 | B9: Integración funcional completa de los siete sistemas (diseño) | C9: Los siete | D9: N6, N7, N10, 296 | E9: 47480 | F9: Motor contable y Evaluación cubren todos los procesos diseñados hasta dic 2029 | G9: Coordinación del Proyecto | H9: No verificable: el .mpp no programa la construcción (C3)

Sheet Evaluación transversal
A1: Caso 7: no se crea un módulo de Evaluación por sistema.
A2: Resultado a evaluar | B2: Sistema que produce los datos | C2: Proceso responsable de evaluarlo
A3: Ejecución del gasto (certificación, compromiso, devengado) | B3: Presupuesto, Abastecimiento, GFRH | C3: Evaluación presupuestaria (366–373); Estados presupuestales (359)
A4: Planillas e ingresos del personal | B4: GFRH | C4: Seguimiento dinámico del gasto (368); Estados presupuestales (359)
A5: Adquisiciones y contratos | B5: Abastecimiento | C5: Análisis de calidad del gasto (373); Seguimiento de metas (366–367)
A6: Bienes, almacén y activos | B6: Abastecimiento | C6: Estados financieros (358); Consolidación contable (357)
A7: Ingresos, pagos y liquidez | B7: Tesorería | C7: Estados financieros (358); Estadísticas de Finanzas Públicas (364); Cuenta General (363)
A8: Deuda pública | B8: Endeudamiento | C8: Estadísticas de deuda (288–289); Estadísticas de Finanzas Públicas (364); Cuenta General (363)
A9: Ejecución de inversiones | B9: Inversiones | C9: Seguimiento físico-financiero, ex post y sostenibilidad (350–352)
A10: Procesos diseñados en 2029 (deuda etapa 2, almacén) | B10: Endeudamiento, Abastecimiento | C10: Validación de integración con CGR y EFP (N10)

Sheet Plan de acción
A1: Plan de implementación de la solución. Nivel de decisión: CAF, Varios CAF, Coordinación o UCP.
A2: Prioridad | B2: Tipo de acción | C2: Acción | D2: Sistema | E2: CAF o responsable por validar | F2: Fecha límite propuesta | G2: Entregable | H2: Nivel de decisión
A3: 1 | B3: Inmediata | C3: Aprobar el Escenario 2 como base de la reprogramación | D3: Transversal | E3: Coordinación del Proyecto y UCP | F3: 13/11/2026 | G3: Acta de aprobación | H3: UCP
A4: 1 | B4: Inmediata | C4: Decidir la salida de StandBy de la PMI y PMIE (147) | D4: Inversiones | E4: CAF Inversiones → Coordinación | F4: 30/10/2026 | G4: Decisión DEC-4 | H4: Coordinación
A5: 1 | B5: Inmediata | C5: Cerrar formalmente los 6 catálogos vencidos al 99 % (25, 46, 59, 60, 62, 63) | D5: Presupuesto | E5: CAF Presupuesto | F5: 13/11/2026 | G5: MFD aprobados | H5: CAF
A6: 1 | B6: Inmediata | C6: Confirmar la fuente contable de transición (escenario A) | D6: Contabilidad | E6: CAF Contabilidad → Coordinación | F6: 30/11/2026 | G6: Decisión DEC-3 | H6: Coordinación
A7: 1 | B7: Inmediata | C7: Aprobar la estructura del catálogo relacional Deuda–Inversión (M5) | D7: Endeudamiento, Inversiones | E7: CAF Endeudamiento + CAF Inversiones | F7: 30/11/2026 | G7: Estructura aprobada | H7: Varios CAF
A8: 2 | B8: Reprogramación | C8: Depurar el .mpp: duplicados 141–142 y 69/75, fila 133, «<Tarea nueva>» (81) y Estado UCP | D8: Transversal | E8: PMO | F8: 13/11/2026 | G8: .mpp depurado | H8: —
